<?xml version="1.0"?>
<robot xmlns:xi="http://www.w3.org/2001/XInclude"
       xmlns:gazebo="http://playerstage.sourceforge.net/gazebo/xmlschema/#gz"
       xmlns:model="http://playerstage.sourceforge.net/gazebo/xmlschema/#model"
       xmlns:sensor="http://playerstage.sourceforge.net/gazebo/xmlschema/#sensor"
       xmlns:body="http://playerstage.sourceforge.net/gazebo/xmlschema/#body"
       xmlns:geom="http://playerstage.sourceforge.net/gazebo/xmlschema/#geom"
       xmlns:joint="http://playerstage.sourceforge.net/gazebo/xmlschema/#joint"
       xmlns:interface="http://playerstage.sourceforge.net/gazebo/xmlschema/#interface"
       xmlns:rendering="http://playerstage.sourceforge.net/gazebo/xmlschema/#rendering"
       xmlns:renderable="http://playerstage.sourceforge.net/gazebo/xmlschema/#renderable"
       xmlns:controller="http://playerstage.sourceforge.net/gazebo/xmlschema/#controller"
       xmlns:physics="http://playerstage.sourceforge.net/gazebo/xmlschema/#physics"
       xmlns:xacro="http://playerstage.sourceforge.net/gazebo/xmlschema/#interface"
       name="guardian">

  <!-- common stuff -->
  <include filename="$(find cob_description)/urdf/common.xacro" />
  <include filename="$(find schunk_description)/urdf/materials.urdf.xacro" />
  <include filename="$(find cob_description)/gazebo/gazebo.urdf.xacro" />
  <!--include filename="$(find carlos_controller)/urdf/sk14.gazebo.xacro" /-->

  <!-- calibration -->
  <include filename="$(find schunk_hardware_config)/powerball/calibration/calibration.urdf.xacro" />

  <!-- schunk powerball -->
  <include filename="$(find carlos_controller)/urdf/powerball.urdf.xacro" />

  <!-- Koco SK14 stud welding tool -->
  <include filename="$(find carlos_controller)/urdf/sk14.urdf.xacro"/>

  <!-- BASE FOOTPRINT -->
  <!-- base_footprint is a fictitious link(frame) that is on the ground right below robot_base_link origin,
             navigation stack depends on this frame -->
  <link name="base_footprint">
      <inertial>
          <mass value="0.0001" />
          <origin xyz="0 0 0" />
      <inertia ixx="0.0001" ixy="0.0" ixz="0.0"
                         iyy="0.0001" iyz="0.0" 
                         izz="0.0001" />
      </inertial>

      <visual>
          <origin xyz="0 0 0" rpy="0 0 0" />
          <geometry>
             <box size="0.001 0.001 0.001" />
          </geometry>
      </visual>

      <collision>
          <origin xyz="0 0 0.0" rpy="0 0 0" />
          <geometry>
            <box size="0.001 0.001 0.001" />
         </geometry>
     </collision>
  </link>

  <gazebo reference="base_footprint">
    <material>Gazebo/Green</material>
    <turnGravityOff>false</turnGravityOff>
  </gazebo>

  <joint name="base_footprint_joint" type="fixed">
     <!--NB: While you would think this would make it go up, it is oddly reversed.
      This moves the joint to 0,0,0 where we want it for rviz, etc. -->
     <!-- origin xyz="0 0 0.130" rpy="0 0 0" / -->
     <origin xyz="0 0 0.186" rpy="0 0 0" />
     <parent link="base_footprint"/>
     <child link="robot_base_link" />
  </joint>


  <!-- ROBOT_BASE_LINK (RED) -->
  <link name="robot_base_link">
    <inertial>
      <mass value="95.0" />
      <origin xyz="0 0 0" />
      <inertia  ixx="3.737" ixy="0.008"  ixz="-0.144"  iyy="8.311"  iyz="-0.004"  izz="8.893" />
    </inertial>
    <visual>
       <origin xyz="0 0 0" rpy="0 0 0" />
       <geometry>
	 <mesh filename="package://guardian_description/meshes/chassis/v6/chassisV6.stl"/>
       </geometry>
    </visual>
    <collision>
       <origin xyz="0 0 0.06" rpy="0 0 0 " />
       <geometry>
         <mesh filename="package://guardian_description/meshes/chassis/v6/chassisV6.stl"/>
	 <!-- box size = "1.0 0.4 0.2"/ -->
       </geometry>
    </collision>     
  </link>
  <gazebo reference="robot_base_link">
    <material>Gazebo/Red</material>
    <turnGravityOff>false</turnGravityOff>
  </gazebo>


  <!-- LEFT TRACK (BLACK) -->
  <link name="left_track">
    <inertial>
      <mass value="1.250" />
      <origin xyz="0 0 0" /> 
      <inertia  ixx="0.0109375" ixy="0.0"  ixz="0.0"  iyy="0.021125"  iyz="0.0"  izz="0.0109375" />
    </inertial>
    <visual>
        <origin xyz="0 0 0" rpy="0 0 0" /> 
        <geometry>
	 <mesh filename="package://guardian_description/meshes/others/v5/trackV5_l.stl"/>
        </geometry>
	<material name="black">
  		<color rgba="0.1 0.1 0.1 1"/>
      	</material>
    </visual>
    <collision>
       <origin xyz="0 0 0" rpy="0 0 0" />
       <geometry>
         <mesh filename="package://guardian_description/meshes/others/v5/trackV5_l.stl"/>
       </geometry>
    </collision>
  </link>
  <gazebo reference="left_track">
    <material>Gazebo/FlatBlack</material>
    <turnGravityOff>false</turnGravityOff>
  </gazebo>

  <joint name="joint_left_track" type="fixed">
    <parent link="robot_base_link"/>
    <child link="left_track"/>
    <origin xyz="0.0 0.0 0.0" rpy="0 0 0" /> 
  </joint>


  <!-- RIGHT TRACK (BLACK) -->
  <link name="right_track">
    <inertial>
      <mass value="1.250" />
      <origin xyz="0 0 0" /> 
      <inertia  ixx="0.0109375" ixy="0.0"  ixz="0.0"  iyy="0.021125"  iyz="0.0"  izz="0.0109375" />
    </inertial>
    <visual>
       <origin xyz="0 0 0" rpy="0 0 0" /> 
       <geometry>
	 <mesh filename="package://guardian_description/meshes/others/v5/trackV5_l.stl"/>
       </geometry>
	<material name="black">
		<color rgba="0.1 0.1 0.1 1"/>
      	</material>
    </visual>
    <collision>
       <origin xyz="0 0 0" rpy="0 0 0" />
       <geometry>
         <mesh filename="package://guardian_description/meshes/others/v5/trackV5_l.stl"/>
       </geometry>
    </collision>
  </link>
  <gazebo reference="right_track">
    <material>Gazebo/FlatBlack</material>
    <turnGravityOff>false</turnGravityOff>
  </gazebo>

  <joint name="joint_right_track" type="fixed">
    <parent link="robot_base_link"/>
    <child link="right_track"/>
    <origin xyz="0.0 0.0 0.0" rpy="0 0 3.1415926535" /> 
    <!-- axis xyz="0 1 0" rpy="0 0 0" / -->
  </joint>



  <!-- BACK LEFT WHEEL (GREY) -->
  <link name="back_left_wheel">
    <inertial>
      <mass value="4.5" />
      <origin xyz="0 0 0" /> 
      <inertia  ixx="0.059" ixy="0.0"  ixz="0.0"  iyy="0.055"  iyz="0.0"  izz="0.059" />
    </inertial>
    <visual>
       <origin xyz="0 0 0" rpy="0 0 3.1416" /> 
       <geometry>
	 <mesh filename="package://guardian_description/meshes/wheel.stl"/>
       </geometry>
	<material name="grey">
		<color rgba="0.3 0.3 0.3 1"/>
      	</material>
    </visual>
    <collision>
       <origin xyz="0 0 0" rpy="0 0 0" />
       <geometry>
         <mesh filename="package://guardian_description/meshes/wheel.stl"/>
       </geometry>
    </collision>
  </link>
  <gazebo reference="back_left_wheel">
    <mu1 value="10.0"/>
    <mu2 value="0.5"/> 
    <fdir1 value="1 0 0"/>
    <material>Gazebo/Grey</material>
    <turnGravityOff>false</turnGravityOff>
  </gazebo>

  <joint name="joint_back_left_wheel" type="continuous">
    <parent link="robot_base_link"/>
    <child link="back_left_wheel"/>
    <origin xyz="-0.30 0.265 0" rpy="0 0 0" /> 
    <axis xyz="0 1 0" rpy="0 0 0" />
    <limit effort="100" velocity="100"/>
    <joint_properties damping="0.0" friction="0.0"/>
  </joint>

  <transmission name="joint_blw_trans" type="pr2_mechanism_model/SimpleTransmission">
     <actuator name="joint_blw_motor" />
     <joint name="joint_back_left_wheel" />
     <mechanicalReduction>1</mechanicalReduction>
     <motorTorqueConstant>1</motorTorqueConstant>
  </transmission>


  <!-- BACK RIGHT WHEEL (BLACK) -->
  <link name="back_right_wheel">
    <inertial>
      <mass value="4.5" />
      <origin xyz="0 0 0" />
      <inertia  ixx="0.059" ixy="0.0"  ixz="0.0"  iyy="0.055"  iyz="0.0"  izz="0.059" />
    </inertial>
    <visual>
       <origin xyz="0 0 0" rpy="0 0 0" /> 
       <geometry>
         <mesh filename="package://guardian_description/meshes/wheel.stl"/>
       </geometry>
	<material name="gray">
		<color rgba="0.3 0.3 0.3 1"/>
      	</material>
    </visual>
    <collision>
       <origin xyz="0 0 0" rpy="0 0 0" /> 
       <geometry>
         <mesh filename="package://guardian_description/meshes/wheel.stl"/>
       </geometry>
    </collision>
  </link>
  <gazebo reference="back_right_wheel">
    <mu1 value="10.0"/> <!-- 2.0 -->
    <mu2 value="0.5"/> <!-- 0.5 -->
    <fdir1 value="1 0 0"/>
    <material>Gazebo/Grey</material>
    <turnGravityOff>false</turnGravityOff>
  </gazebo>

  <joint name="joint_back_right_wheel" type="continuous">
    <parent link="robot_base_link"/>
    <child link="back_right_wheel"/>
    <origin xyz="-0.30 -0.265 0" rpy="0 0 0" />
    <axis xyz="0 1 0" />
    <limit effort="100" velocity="100"/>
    <joint_properties damping="0.0" friction="0.0"/>
  </joint>

  <transmission name="joint_brw_trans" type="pr2_mechanism_model/SimpleTransmission">
     <actuator name="joint_brw_motor" />
     <joint name="joint_back_right_wheel" />
     <mechanicalReduction>1</mechanicalReduction>
     <motorTorqueConstant>1</motorTorqueConstant>
  </transmission>

  <!-- FRONT LEFT WHEEL (GREY) -->
  <link name="front_left_wheel">
    <inertial>
      <mass value="4.5" />
      <origin xyz="0 0 0" />
      <inertia  ixx="0.059" ixy="0.0"  ixz="0.0"  iyy="0.055"  iyz="0.0"  izz="0.059" />
    </inertial>
    <visual>
       <origin xyz="0 0 0" rpy="0 0 3.1416" /> 
       <geometry>
         <mesh filename="package://guardian_description/meshes/wheel.stl"/>
       </geometry>
	<material name="grey">
		<color rgba="0.3 0.3 0.3 1"/>
      	</material>
    </visual>
    <collision>
       <origin xyz="0 0 0" rpy="0 0 0" /> 
       <geometry>
         <mesh filename="package://guardian_description/meshes/wheel.stl"/>
       </geometry>
    </collision>
  </link>
  <gazebo reference="front_left_wheel">
    <mu1 value="10.0"/> <!-- 2.0 -->
    <mu2 value="0.5"/> <!-- 0.5 -->
    <fdir1 value="1 0 0"/>
    <material>Gazebo/Grey</material>
    <turnGravityOff>false</turnGravityOff>
  </gazebo>

  <joint name="joint_front_left_wheel" type="continuous">
    <parent link="robot_base_link"/>
    <child link="front_left_wheel"/>
    <origin xyz="0.30 0.265 0" rpy="0 0 0" />
    <axis xyz="0 1 0" />
    <limit effort="100" velocity="100"/>
    <joint_properties damping="0.0" friction="0.0"/>
  </joint>

  <transmission name="joint_flw_trans" type="pr2_mechanism_model/SimpleTransmission">
     <actuator name="joint_flw_motor" />
     <joint name="joint_front_left_wheel" />
     <mechanicalReduction>1</mechanicalReduction>
     <motorTorqueConstant>1</motorTorqueConstant>
  </transmission>


  <!-- FRONT RIGHT WHEEL (GREY) -->
  <link name="front_right_wheel">
    <inertial>
      <mass value="4.5" />
      <origin xyz="0 0 0" />
      <inertia  ixx="0.059" ixy="0.0"  ixz="0.0"  iyy="0.055"  iyz="0.0"  izz="0.059" />
    </inertial>
    <visual>
       <origin xyz="0 0 0" rpy="0 0 0" /> 
       <geometry>
         <mesh filename="package://guardian_description/meshes/wheel.stl"/>
       </geometry>
	<material name="grey">
		<color rgba="0.3 0.3 0.3 1"/>
      	</material>
    </visual>
    <collision>
       <origin xyz="0 0 0" rpy="0 0 0" /> 
       <geometry>
         <mesh filename="package://guardian_description/meshes/wheel.stl"/> 
       </geometry>
    </collision>
  </link>
  <gazebo reference="front_right_wheel">
    <mu1 value="10.0"/> <!-- 2.0 -->
    <mu2 value="0.5"/> <!-- 0.5 -->
    <fdir1 value="1 0 0"/>
    <material>Gazebo/Grey</material>
    <turnGravityOff>false</turnGravityOff>
  </gazebo>

  <joint name="joint_front_right_wheel" type="continuous">
    <parent link="robot_base_link"/>
    <child link="front_right_wheel"/>
    <origin xyz="0.30 -0.265 0" rpy="0 0 0" />
    <axis xyz="0 1 0" />
    <limit effort="100" velocity="100"/>
    <joint_properties damping="0.0" friction="0.0"/>
  </joint>

  <transmission name="joint_frw_trans" type="pr2_mechanism_model/SimpleTransmission">
     <actuator name="joint_frw_motor" />
     <joint name="joint_front_right_wheel" />
     <mechanicalReduction>1</mechanicalReduction>
     <motorTorqueConstant>1</motorTorqueConstant>
  </transmission>


  <!-- HOKUYO SENSOR -->
  <joint name="hokuyo_laser_joint" type="fixed">
     <axis xyz="0 1 0" />
     <origin xyz="0.12 0 0.285"/>
     <parent link="robot_base_link"/>
     <child link="hokuyo_laser_link"/>
  </joint>
  <link name="hokuyo_laser_link" type="laser">
     <inertial>
       <mass value="0.001" />
       <origin xyz="0 0 0" rpy="0 0 0" />
       <inertia ixx="0.0001" ixy="0" ixz="0" iyy="0.000001" iyz="0" izz="0.0001" />
    </inertial>
  </link>

  <!-- This adds a visual box to allow us to see the Hokuyo in rviz/gazebo -->
  <joint name="hokuyo_laser_box_joint" type="fixed">
    <origin xyz="0 0 0" rpy="0 0 0" />
    <parent link="hokuyo_laser_link" />
    <child link="hokuyo_laser_box_link"/>
  </joint>
  <link name="hokuyo_laser_box_link">
    <inertial>
      <mass value="0.01" />
      <origin xyz="0 0 0" />
      <inertia ixx="0.001"  ixy="0.0"  ixz="0.0"
               iyy="0.001"  iyz="0.0"
               izz="0.001" />
    </inertial>
    <visual>
      <origin xyz="0 0 0" rpy="0 0 0"/>
      <geometry>
        <!--box size="0.05 0.05 0.1" /-->
	<mesh filename= "package://pr2_description/meshes/tilting_laser_v0/hok_tilt.stl" scale="0.5 0.5 0.5"/>
      </geometry>
    </visual>
    <collision>
      <origin xyz="0 0 0" rpy="0 0 0"/>
      <geometry>
        <box size="0.05 0.05 0.1" />
      </geometry>
    </collision>
  </link>

  <gazebo reference="hokuyo_laser_box_link">
    <material>Gazebo/FlatBlack</material>
    <turnGravityOff>false</turnGravityOff>
  </gazebo>

  <!-- IMU SENSOR -->

  <joint name="imu_joint" type="fixed">
      <axis xyz="1 0 0"/> <!-- 0 1 0 -->
      <origin xyz="0 0 0.2825"/>
      <parent link="robot_base_link"/>
      <child link="imu_link"/>
  </joint>


  <link name="imu_link">
      <inertial>
        <mass value="0.001"/>
        <origin rpy="0 0 0" xyz="0 0 0"/>
        <inertia ixx="0.0001" ixy="0" ixz="0" iyy="0.000001" iyz="0" izz="0.0001"/>
      </inertial>
      <visual>
        <origin rpy="0 0 0" xyz="0 0 0"/>
        <geometry>
          <box size="0.001 0.001 0.001"/>
        </geometry>
      </visual>
      <collision>
        <origin rpy="0 0 0" xyz="0 0 0"/>
        <geometry>
          <box size=".001 .001 .001"/>
        </geometry>
      </collision>
  </link>


 <!-- foot for arm -->
  <link name="base_link">
    <visual>
      <origin xyz="0 0 0" rpy="0 0 0" />
      <geometry>
	<cylinder radius="0.065" length="0.135"/>
      </geometry>
      <material name="Schunk/DarkGrey" />
    </visual>
    
    <collision>
      <origin xyz="0 0 0" rpy="0 0 0" />
      <geometry>
	<cylinder radius="0.065" length="0.135"/>
      </geometry>
    </collision>
    
    <inertial>
      <origin xyz="0 0 0" rpy="0 0 0" />
      <mass value="3" />
      <inertia ixx="0.1" ixy="0" ixz="0" iyy="0.1" iyz="0" izz="0.1" />
    </inertial>
  </link>

  <joint name="arm_base_joint" type="fixed">
    <origin xyz="0.2 0 0.372" rpy="0 0 0"/>
    <parent link="robot_base_link"/>
    <child link="base_link"/>
  </joint>
  <!-- arm -->

  <xacro:schunk_powerball name="arm" parent="base_link">
    <origin xyz="0 0 0.025" rpy="0 0 0" />
  </xacro:schunk_powerball>

  <xacro:koco_sk14 name="tool" parent="arm_tool0">
    <origin xyz="0 0 0" rpy="0 0 0" />
  </xacro:koco_sk14>

</robot>

